Workbook

Sheet Data
A1: Date | B1: XOM | C1: GE | D1: HD | E1: JNJ | F1: VZ | G1: WMT | H1: BAC | I1: NFLX | J1: RF | K1: Market
A2: 42398 | B2: -0.0012828541 | C2: -0.065810569 | D2: -0.049073707 | E2: 0.01674456 | F2: 0.093357854 | G2: 0.082544886 | H2: -0.15983361 | I2: -0.19706243 | J2: 0.0001 | K2: -0.05073534
A3: 42429 | B3: 0.038921043 | C3: 0.0092783161 | D3: -0.013040707 | E3: 0.014553778 | F3: 0.015209092 | G3: -0.00030145075 | H3: -0.11456859 | I3: 0.017095027 | J3: 0.0002 | K3: -0.004128355
A4: 42460 | B4: 0.042919461 | C4: 0.090940341 | D4: 0.080567107 | E4: 0.028419333 | F4: 0.066035919 | G4: 0.039945759 | H4: 0.083865814 | I4: 0.09442243 | J4: 0.0002 | K4: 0.06599111
A5: 42489 | B5: 0.057542834 | C5: -0.032714717 | D5: 0.003447551 | E5: 0.035859566 | F5: -0.047614701 | G5: -0.023653017 | H5: 0.076923072 | I5: -0.11933879 | J5: 0.0001 | K5: 0.00269937
A6: 42521 | B6: 0.015497682 | C6: -0.016910585 | D6: -0.0080663553 | E6: 0.012580305 | F6: -0.00078518066 | G6: 0.065948792 | H6: 0.015796671 | I6: 0.13928692 | J6: 0.0001 | K6: 0.01532949
A7: 42551 | B7: 0.053021807 | C7: 0.048957989 | D7: -0.033530071 | E7: 0.076404296 | F7: 0.097053014 | G7: 0.031647328 | H7: -0.099391446 | I7: -0.10812125 | J7: 0.0002 | K7: 0.0009060735
A8: 42580 | B8: -0.051098794 | C8: -0.010800513 | D8: 0.082621999 | E8: 0.032399014 | F8: 0.0024176163 | G8: -0.00068468123 | H8: 0.091936648 | I8: -0.0025142473 | J8: 0.0002 | K8: 0.03560981
A9: 42613 | B9: -0.01191678 | C9: 0.0032113162 | D9: -0.024811996 | E9: -0.040645268 | F9: -0.0555856 | G9: -0.014115373 | H9: 0.1190476 | I9: 0.067945175 | J9: 0.0002 | K9: -0.001219176
A10: 42643 | B10: 0.001606603 | C10: -0.044494204 | D10: -0.040560711 | E10: -0.010139091 | F10: -0.0066883676 | G10: 0.0095184809 | H10: -0.030359343 | I10: 0.011287902 | J10: 0.0002 | K10: -0.001234483
A11: 42674 | B11: -0.045371208 | C11: -0.017555721 | D11: -0.051833935 | E11: -0.01811563 | F11: -0.063534074 | G11: -0.029118219 | H11: 0.054313123 | I11: 0.26707253 | J11: 0.0002 | K11: -0.01942562
A12: 42704 | B12: 0.056769125 | C12: 0.057044666 | D12: 0.066224009 | E12: -0.033537328 | F12: 0.037422102 | G12: 0.0058555226 | H12: 0.28454551 | I12: -0.063025564 | J12: 0.0001 | K12: 0.03417445
A13: 42734 | B13: 0.033906061 | C13: 0.035110537 | D13: 0.036166988 | E13: 0.035130244 | F13: 0.069739468 | G13: -0.011500746 | H13: 0.046401493 | I13: 0.058119684 | J13: 0.0003 | K13: 0.01820075
... A97: 45289 | B97: -0.026863875 | C97: 0.048522118 | D97: 0.1054579 | E97: 0.013448867 | F97: -0.01643624 | G97: 0.016250186 | H97: 0.10429644 | I97: 0.027238019 | J97: 0.0043 | K97: 0.04422917

Sheet inputs_new
B1: XOM | C1: GE | D1: HD | E1: JNJ | F1: VZ | G1: WMT | H1: BAC | I1: NFLX | K1: rf = 3%
A2: avarage return | B2: =AVERAGE(Data!B2:B97) -> 0.010006472 | C2: =AVERAGE(Data!C2:C97) -> 0.0027939853 | D2: =AVERAGE(Data!D2:D97) -> 0.014139894 | E2: =AVERAGE(Data!E2:E97) -> 0.0077462473 | F2: =AVERAGE(Data!F2:F97) -> 0.0032866288 | G2: =AVERAGE(Data!G2:G97) -> 0.012912393 | H2: =AVERAGE(Data!H2:H97) -> 0.013215151 | I2: =AVERAGE(Data!I2:I97) -> 0.022894013
A3: sigma | B3: =_xlfn.STDEV.S(Data!B2:B97) -> 0.084575546 | C3: =_xlfn.STDEV.S(Data!C2:C97) -> 0.10701119 | D3: =_xlfn.STDEV.S(Data!D2:D97) -> 0.064818623 | E3: =_xlfn.STDEV.S(Data!E2:E97) -> 0.046415644 | F3: =_xlfn.STDEV.S(Data!F2:F97) -> 0.051226708 | G3: =_xlfn.STDEV.S(Data!G2:G97) -> 0.05191387 | H3: =_xlfn.STDEV.S(Data!H2:H97) -> 0.090971722 | I3: =_xlfn.STDEV.S(Data!I2:I97) -> 0.12075074
A4: variance | B4: =_xlfn.VAR.S(Data!B2:B97) -> 0.007153023 | C4: =_xlfn.VAR.S(Data!C2:C97) -> 0.011451394 | D4: =_xlfn.VAR.S(Data!D2:D97) -> 0.0042014538 | E4: =_xlfn.VAR.S(Data!E2:E97) -> 0.002154412 | F4: =_xlfn.VAR.S(Data!F2:F97) -> 0.0026241756 | G4: =_xlfn.VAR.S(Data!G2:G97) -> 0.0026950499 | H4: =_xlfn.VAR.S(Data!H2:H97) -> 0.0082758541 | I4: =_xlfn.VAR.S(Data!I2:I97) -> 0.014580741
A7: Covariance matrix population | B7: XOM | C7: GE | D7: HD | E7: JNJ | F7: VZ | G7: WMT | H7: BAC | I7: NFLX
A8: XOM | B8: =VARP(Data!$B$2:$B$1048576) -> 0.0070785124
A9: GE | B9: 0.004000222 | C9: =VARP(Data!$C$2:$C$1048576) -> 0.011332109 | G9: =_xlfn.COVARIANCE.S(Data!B2:B97, Data!C2:C97) -> 0.0040423296
A10: HD | B10: 0.0016564729 | C10: 0.0015173524 | D10: =VARP(Data!$D$2:$D$1048576) -> 0.0041576887
A11: JNJ | B11: 0.0014939664 | C11: 0.00032247959 | D11: 0.0011106261 | E11: =VARP(Data!$E$2:$E$1048576) -> 0.0021319703
A12: VZ | B12: 0.001203219 | C12: 0.0006814554 | D12: 0.00087441947 | E12: 0.00094284447 | F12: =VARP(Data!$F$2:$F$1048576) -> 0.0025968405
A13: WMT | B13: 0.00068219705 | C13: 0.00047880957 | D13: 0.001165654 | E13: 0.0010622793 | F13: 0.00087404752 | G13: =VARP(Data!$G$2:$G$1048576) -> 0.0026669764
A14: BAC | B14: 0.0041307075 | C14: 0.0050034232 | D14: 0.0030798748 | E14: 0.0013401208 | F14: 0.00083294543 | G14: 0.00076431168 | H14: =VARP(Data!$H$2:$H$1048576) -> 0.0081896473
A15: NFLX | B15: 0.00078578855 | C15: 0.0041804613 | D15: 0.0023040798 | E15: 5.9885967e-05 | F15: 0.00018028158 | G15: 0.00075812433 | H15: 0.0037497625 | I15: =VARP(Data!$I$2:$I$1048576) -> 0.014428859
A17: n | B17: =COUNTA(Data!B2:B97) -> 96
A19: Covariance matrix sample | B19: XOM | C19: GE | D19: HD | E19: JNJ | F19: VZ | G19: WMT | H19: BAC | I19: NFLX
A20: XOM | B20: =B8*$B$17/($B$17-1) -> 0.007153023
A21: GE | B21: =B9*$B$17/($B$17-1) -> 0.0040423296 | C21: =C9*$B$17/($B$17-1) -> 0.011451394
A22: HD | B22: =B10*$B$17/($B$17-1) -> 0.0016739095 | C22: =C10*$B$17/($B$17-1) -> 0.0015333245 | D22: =D10*$B$17/($B$17-1) -> 0.0042014538
A23: JNJ | B23: =B11*$B$17/($B$17-1) -> 0.0015096923 | C23: =C11*$B$17/($B$17-1) -> 0.00032587411 | D23: =D11*$B$17/($B$17-1) -> 0.0011223169 | E23: =E11*$B$17/($B$17-1) -> 0.002154412
A24: VZ | B24: =B12*$B$17/($B$17-1) -> 0.0012158845 | C24: =C12*$B$17/($B$17-1) -> 0.00068862861 | D24: =D12*$B$17/($B$17-1) -> 0.00088362389 | E24: =E12*$B$17/($B$17-1) -> 0.00095276915 | F24: =F12*$B$17/($B$17-1) -> 0.0026241756
A25: WMT | B25: =B13*$B$17/($B$17-1) -> 0.00068937807 | C25: =C13*$B$17/($B$17-1) -> 0.00048384967 | D25: =D13*$B$17/($B$17-1) -> 0.0011779241 | E25: =E13*$B$17/($B$17-1) -> 0.0010734612 | F25: =F13*$B$17/($B$17-1) -> 0.00088324802 | G25: =G13*$B$17/($B$17-1) -> 0.0026950499
A26: BAC | B26: =B14*$B$17/($B$17-1) -> 0.0041741886 | C26: =C14*$B$17/($B$17-1) -> 0.0050560908 | D26: =D14*$B$17/($B$17-1) -> 0.0031122945 | E26: =E14*$B$17/($B$17-1) -> 0.0013542273 | F26: =F14*$B$17/($B$17-1) -> 0.00084171328 | G26: =G14*$B$17/($B$17-1) -> 0.00077235706 | H26: =H14*$B$17/($B$17-1) -> 0.0082758541
A27: NFLX | B27: =B15*$B$17/($B$17-1) -> 0.00079406001 | C27: =C15*$B$17/($B$17-1) -> 0.0042244662 | D27: =D15*$B$17/($B$17-1) -> 0.0023283332 | E27: =E15*$B$17/($B$17-1) -> 6.0516346e-05 | F27: =F15*$B$17/($B$17-1) -> 0.00018217928 | G27: =G15*$B$17/($B$17-1) -> 0.00076610459 | H27: =H15*$B$17/($B$17-1) -> 0.0037892337 | I27: =I15*$B$17/($B$17-1) -> 0.014580741

Sheet Inputs
B1: XOM | C1: GE | D1: HD | E1: JNJ | F1: VZ | G1: WMT | H1: BAC | I1: NFLX
A3: Monthly mu | B3: =AVERAGE(Data!B2:B97) -> 0.010006472 | C3: =AVERAGE(Data!C2:C97) -> 0.0027939853 | D3: =AVERAGE(Data!D2:D97) -> 0.014139894 | E3: =AVERAGE(Data!E2:E97) -> 0.0077462473 | F3: =AVERAGE(Data!F2:F97) -> 0.0032866288 | G3: =AVERAGE(Data!G2:G97) -> 0.012912393 | H3: =AVERAGE(Data!H2:H97) -> 0.013215151 | I3: =AVERAGE(Data!I2:I97) -> 0.022894013
A4: Monthly sigma | B4: =_xlfn.STDEV.S(Data!B2:B97) -> 0.084575546 | C4: =_xlfn.STDEV.S(Data!C2:C97) -> 0.10701119 | D4: =_xlfn.STDEV.S(Data!D2:D97) -> 0.064818623 | E4: =_xlfn.STDEV.S(Data!E2:E97) -> 0.046415644 | F4: =_xlfn.STDEV.S(Data!F2:F97) -> 0.051226708 | G4: =_xlfn.STDEV.S(Data!G2:G97) -> 0.05191387 | H4: =_xlfn.STDEV.S(Data!H2:H97) -> 0.090971722 | I4: =_xlfn.STDEV.S(Data!I2:I97) -> 0.12075074
A5: Annually mu | B5: =B3*12 -> 0.12007767 | C5: =C3*12 -> 0.033527823 | D5: =D3*12 -> 0.16967872 | E5: =E3*12 -> 0.092954968 | F5: =F3*12 -> 0.039439546 | G5: =G3*12 -> 0.15494872 | H5: =H3*12 -> 0.15858181 | I5: =I3*12 -> 0.27472816
A6: Annual sigma | B6: =B4*SQRT(12) -> 0.29297829 | C6: =C4*SQRT(12) -> 0.37069763 | D6: =D4*SQRT(12) -> 0.2245383 | E6: =E4*SQRT(12) -> 0.16078851 | F6: =F4*SQRT(12) -> 0.17745452 | G6: =G4*SQRT(12) -> 0.17983492 | H6: =H4*SQRT(12) -> 0.31513529 | I6: =I4*SQRT(12) -> 0.41829283
A7: Covariance | B7: =_xlfn.COVARIANCE.S(Data!B2:B97, Data!$K$2:$K$97) -> 0.0020644322 | C7: =_xlfn.COVARIANCE.S(Data!C2:C97, Data!$K$2:$K$97) -> 0.0026262887 | D7: =_xlfn.COVARIANCE.S(Data!D2:D97, Data!$K$2:$K$97) -> 0.002205001 | E7: =_xlfn.COVARIANCE.S(Data!E2:E97, Data!$K$2:$K$97) -> 0.0011633491 | F7: =_xlfn.COVARIANCE.S(Data!F2:F97, Data!$K$2:$K$97) -> 0.00085645849 | G7: =_xlfn.COVARIANCE.S(Data!G2:G97, Data!$K$2:$K$97) -> 0.0010360901 | H7: =_xlfn.COVARIANCE.S(Data!H2:H97, Data!$K$2:$K$97) -> 0.0031081259 | I7: =_xlfn.COVARIANCE.S(Data!I2:I97, Data!$K$2:$K$97) -> 0.0028166262
A9: Population covariance matrix
B10: Column 1 | C10: Column 2 | D10: Column 3 | E10: Column 4 | F10: Column 5 | G10: Column 6 | H10: Column 7 | I10: Column 8
A11: Column 1 | B11: =VARP(Data!$B$2:$B$97) -> 0.0070785124
A12: Column 2 | B12: 0.004000222 | C12: =VARP(Data!$C$2:$C$97) -> 0.011332109 | L12: manuell utregning
A13: Column 3 | B13: 0.0016564729 | C13: 0.0015173524 | D13: =VARP(Data!$D$2:$D$97) -> 0.0041576887 | L13: y | N13: mnd
A14: Column 4 | B14: 0.0014939664 | C14: 0.00032247959 | D14: 0.0011106261 | E14: =VARP(Data!$E$2:$E$97) -> 0.0021319703 | L14: =(0.5^2*B23)+(0.5^2*C24)+(2*0.5*0.5*B24) -> 0.0066722692 | N14: =(0.5*B4)+(0.5*C4)+(2*0.5*0.5*C23) -> 0.097814532
A15: Column 5 | B15: 0.001203219 | C15: 0.0006814554 | D15: 0.00087441947 | E15: 0.00094284447 | F15: =VARP(Data!$F$2:$F$97) -> 0.0025968405 | L15: =SQRT(L14) -> 0.081683959 | N15: =SQRT(N14) -> 0.31275315
A16: Column 6 | B16: 0.00068219705 | C16: 0.00047880957 | D16: 0.001165654 | E16: 0.0010622793 | F16: 0.00087404752 | G16: =VARP(Data!$G$2:$G$97) -> 0.0026669764 | L16: =SQRT(L15) -> 0.28580406
A17: Column 7 | B17: 0.0041307075 | C17: 0.0050034232 | D17: 0.0030798748 | E17: 0.0013401208 | F17: 0.00083294543 | G17: 0.00076431168 | H17: =VARP(Data!$H$2:$H$97) -> 0.0081896473
A18: Column 8 | B18: 0.00078578855 | C18: 0.0041804613 | D18: 0.0023040798 | E18: 5.9885967e-05 | F18: 0.00018028158 | G18: 0.00075812433 | H18: 0.0037497625 | I18: =VARP(Data!$I$2:$I$97) -> 0.014428859
A20: N | B20: =COUNT(Data!B2:B97) -> 96
A22: Samle covariance matrix | B22: =B1 -> XOM | C22: =C1 -> GE | D22: =D1 -> HD | E22: =E1 -> JNJ | F22: =F1 -> VZ | G22: =G1 -> WMT | H22: =H1 -> BAC | I22: =I1 -> NFLX
A23: {=TRANSPOSE(B22:I22)} -> XOM | B23: =B11*$B$20/($B$20-1) -> 0.007153023 | C23: {=TRANSPOSE(B24:B30)} -> 0.0040423296 | D23: 0.0016739095 | E23: 0.0015096923 | F23: 0.0012158845 | G23: 0.00068937807 | H23: 0.0041741886 | I23: 0.00079406001
A24: GE | B24: =B12*$B$20/($B$20-1) -> 0.0040423296 | C24: =C12*$B$20/($B$20-1) -> 0.011451394 | D24: {=TRANSPOSE(C25:C30)} -> 0.0015333245 | E24: 0.00032587411 | F24: 0.00068862861 | G24: 0.00048384967 | H24: 0.0050560908 | I24: 0.0042244662
A25: HD | B25: =B13*$B$20/($B$20-1) -> 0.0016739095 | C25: =C13*$B$20/($B$20-1) -> 0.0015333245 | D25: =D13*$B$20/($B$20-1) -> 0.0042014538 | E25: {=TRANSPOSE(D26:D30)} -> 0.0011223169 | F25: 0.00088362389 | G25: 0.0011779241 | H25: 0.0031122945 | I25: 0.0023283332
A26: JNJ | B26: =B14*$B$20/($B$20-1) -> 0.0015096923 | C26: =C14*$B$20/($B$20-1) -> 0.00032587411 | D26: =D14*$B$20/($B$20-1) -> 0.0011223169 | E26: =E14*$B$20/($B$20-1) -> 0.002154412 | F26: {=TRANSPOSE(E27:E30)} -> 0.00095276915 | G26: 0.0010734612 | H26: 0.0013542273 | I26: 6.0516346e-05
A27: VZ | B27: =B15*$B$20/($B$20-1) -> 0.0012158845 | C27: =C15*$B$20/($B$20-1) -> 0.00068862861 | D27: =D15*$B$20/($B$20-1) -> 0.00088362389 | E27: =E15*$B$20/($B$20-1) -> 0.00095276915 | F27: =F15*$B$20/($B$20-1) -> 0.0026241756 | G27: {=TRANSPOSE(F28:F30)} -> 0.00088324802 | H27: 0.00084171328 | I27: 0.00018217928
A28: WMT | B28: =B16*$B$20/($B$20-1) -> 0.00068937807 | C28: =C16*$B$20/($B$20-1) -> 0.00048384967 | D28: =D16*$B$20/($B$20-1) -> 0.0011779241 | E28: =E16*$B$20/($B$20-1) -> 0.0010734612 | F28: =F16*$B$20/($B$20-1) -> 0.00088324802 | G28: =G16*$B$20/($B$20-1) -> 0.0026950499 | H28: {=TRANSPOSE(G29:G30)} -> 0.00077235706 | I28: 0.00076610459
A29: BAC | B29: =B17*$B$20/($B$20-1) -> 0.0041741886 | C29: =C17*$B$20/($B$20-1) -> 0.0050560908 | D29: =D17*$B$20/($B$20-1) -> 0.0031122945 | E29: =E17*$B$20/($B$20-1) -> 0.0013542273 | F29: =F17*$B$20/($B$20-1) -> 0.00084171328 | G29: =G17*$B$20/($B$20-1) -> 0.00077235706 | H29: =H17*$B$20/($B$20-1) -> 0.0082758541 | I29: {=TRANSPOSE(H30)} -> 0.0037892337
A30: NFLX | B30: =B18*$B$20/($B$20-1) -> 0.00079406001 | C30: =C18*$B$20/($B$20-1) -> 0.0042244662 | D30: =D18*$B$20/($B$20-1) -> 0.0023283332 | E30: =E18*$B$20/($B$20-1) -> 6.0516346e-05 | F30: =F18*$B$20/($B$20-1) -> 0.00018217928 | G30: =G18*$B$20/($B$20-1) -> 0.00076610459 | H30: =H18*$B$20/($B$20-1) -> 0.0037892337 | I30: =I18*$B$20/($B$20-1) -> 0.014580741

Sheet Plot Returns_Risk1
A1: Ticker | B1: XOM | C1: GE | D1: HD | E1: JNJ | F1: VZ | G1: WMT | H1: BAC | I1: NFLX | J1: Market
A3: Annual average returns | B3: 0.12007767 | C3: 0.033527823 | D3: 0.16967872 | E3: 0.092954968 | F3: 0.039439546 | G3: 0.15494872 | H3: 0.15858181 | I3: 0.27472816 | J3: 0.11922758
A4: Annual volatility (sigma) | B4: 0.29297829 | C4: 0.37069763 | D4: 0.2245383 | E4: 0.16078851 | F4: 0.17745452 | G4: 0.17983492 | H4: 0.31513529 | I4: 0.41829283 | J4: 0.16054033
A5: Covariance | B5: 0.0020644322 | C5: 0.0026262887 | D5: 0.002205001 | E5: 0.0011633491 | F5: 0.00085645849 | G5: 0.0010360901 | H5: 0.0031081259 | I5: 0.0028166262 | J5: 0.0021477665

Sheet EW Portfolio
B1: Monthly
B2: XOM_avrg | C2: GE_avrg | D2: HD_avrg | E2: JNJ_avrg | F2: VZ_avrg | G2: WMT_avrg | H2: BAC_avrg | I2: NFLX_avrg | J2: RF | K2: Market
A3: Average montly returns | B3: =Inputs!B3 -> 0.010006472 | C3: =Inputs!C3 -> 0.0027939853 | D3: =Inputs!D3 -> 0.014139894 | E3: =Inputs!E3 -> 0.0077462473 | F3: =Inputs!F3 -> 0.0032866288 | G3: =Inputs!G3 -> 0.012912393 | H3: =Inputs!H3 -> 0.013215151 | I3: =Inputs!I3 -> 0.022894013 | J3: =AVERAGE(Data!J2:J97) -> 0.0012145833 | K3: =AVERAGE(Data!K2:K97) -> 0.009935632
A4: Monthly standard deviations (sigma) | B4: =Inputs!B4 -> 0.084575546 | C4: =Inputs!C4 -> 0.10701119 | D4: =Inputs!D4 -> 0.064818623 | E4: =Inputs!E4 -> 0.046415644 | F4: =Inputs!F4 -> 0.051226708 | G4: =Inputs!G4 -> 0.05191387 | H4: =Inputs!H4 -> 0.090971722 | I4: =Inputs!I4 -> 0.12075074 | J4: =_xlfn.STDEV.S(Data!J2:J97) -> 0.0013216401 | K4: =_xlfn.STDEV.S(Data!K2:K97) -> 0.046344002
B5: XOM | C5: GE | D5: HD | E5: JNJ | F5: VZ | G5: WMT | H5: BAC | I5: NFLX | J5: Total
A7: Weights | B7: 0.125 | C7: 0.125 | D7: 0.125 | E7: 0.125 | F7: 0.125 | G7: 0.125 | H7: 0.125 | I7: 0.125 | J7: =SUM(B7:I7) -> 1
A9: EW portfolio | B9: Total | M9: =K3*12 -> 0.11922758
A10: Monthly average returns | B10: =AVERAGE(B3:I3) -> 0.010874348
A11: Sigma | B11: {=SQRT(MMULT(MMULT(B7:I7,Inputs!B23:I30),TRANSPOSE(B7:I7)))} -> 0.047526319
A12: Risk free rate | B12: =B27/12 -> 0.0025
A13: Sharpe Ratio | B13: =(B10-B12)/B11 -> 0.17620443
B15: Annually
B16: XOM_avrg | C16: GE_avrg | D16: HD_avrg | E16: JNJ_avrg | F16: VZ_avrg | G16: WMT_avrg | H16: BAC_avrg | I16: NFLX_avrg | J16: RF | K16: Market
A17: Annual average returns | B17: =B3*12 -> 0.12007767 | C17: =C3*12 -> 0.033527823 | D17: =D3*12 -> 0.16967872 | E17: =E3*12 -> 0.092954968 | F17: =F3*12 -> 0.039439546 | G17: =G3*12 -> 0.15494872 | H17: =H3*12 -> 0.15858181 | I17: =I3*12 -> 0.27472816 | ... K17: =K3*12 -> 0.11922758
A18: Annual standard deviations (sigma) | B18: =B4*SQRT(12) -> 0.29297829 | C18: =C4*SQRT(12) -> 0.37069763 | D18: =D4*SQRT(12) -> 0.2245383 | E18: =E4*SQRT(12) -> 0.16078851 | F18: =F4*SQRT(12) -> 0.17745452 | G18: =G4*SQRT(12) -> 0.17983492 | H18: =H4*SQRT(12) -> 0.31513529 | I18: =I4*SQRT(12) -> 0.41829283 | ... K18: =K4*SQRT(12) -> 0.16054033
A19: Covariance | B19: =_xlfn.COVARIANCE.S(Data!B2:B97, Data!$K$2:$K$97) -> 0.0020644322 | C19: =_xlfn.COVARIANCE.S(Data!C2:C97, Data!$K$2:$K$97) -> 0.0026262887 | D19: =_xlfn.COVARIANCE.S(Data!D2:D97, Data!$K$2:$K$97) -> 0.002205001 | E19: =_xlfn.COVARIANCE.S(Data!E2:E97, Data!$K$2:$K$97) -> 0.0011633491 | F19: =_xlfn.COVARIANCE.S(Data!F2:F97, Data!$K$2:$K$97) -> 0.00085645849 | G19: =_xlfn.COVARIANCE.S(Data!G2:G97, Data!$K$2:$K$97) -> 0.0010360901 | H19: =_xlfn.COVARIANCE.S(Data!H2:H97, Data!$K$2:$K$97) -> 0.0031081259 | I19: =_xlfn.COVARIANCE.S(Data!I2:I97, Data!$K$2:$K$97) -> 0.0028166262 | ... K19: =_xlfn.COVARIANCE.S(Data!K2:K97, Data!$K$2:$K$97) -> 0.0021477665
B20: XOM | C20: GE | D20: HD | E20: JNJ | F20: VZ | G20: WMT | H20: BAC | I20: NFLX | J20: Total
A22: Weights | B22: 0.125 | C22: 0.125 | D22: 0.125 | E22: 0.125 | F22: 0.125 | G22: 0.125 | H22: 0.125 | I22: 0.125 | J22: =SUM(B22:I22) -> 1 | O22: =B11*SQRT(12) -> 0.164636
O23: =0.0022587509751133*SQRT(12) -> 0.0078245429
B24: Annually
A25: Annual average returns | B25: =AVERAGE(B17:I17) -> 0.13049218
A26: Sigma | B26: =B11*SQRT(12) -> 0.164636
A27: Risk free rate | B27: 0.03
A28: Sharpe Ratio | B28: =(B25-B27)/B26 -> 0.61039006

Sheet Min Variance Portfolio
A1: Monthly | G1: n | H1: =COUNTA(B3:I3) -> 8 | I1: EW | J1: =1/H1 -> 0.125
B3: XOM_avrg | C3: GE_avrg | D3: HD_avrg | E3: JNJ_avrg | F3: VZ_avrg | G3: WMT_avrg | H3: BAC_avrg | I3: NFLX_avrg | J3: Sum
A4: Average montly returns | B4: =Inputs!B3 -> 0.010006472 | C4: =Inputs!C3 -> 0.0027939853 | D4: =Inputs!D3 -> 0.014139894 | E4: =Inputs!E3 -> 0.0077462473 | F4: =Inputs!F3 -> 0.0032866288 | G4: =Inputs!G3 -> 0.012912393 | H4: =Inputs!H3 -> 0.013215151 | I4: =Inputs!I3 -> 0.022894013
A5: Monthly standard deviations (sigma) | B5: =Inputs!B4 -> 0.084575546 | C5: =Inputs!C4 -> 0.10701119 | D5: =Inputs!D4 -> 0.064818623 | E5: =Inputs!E4 -> 0.046415644 | F5: =Inputs!F4 -> 0.051226708 | G5: =Inputs!G4 -> 0.05191387 | H5: =Inputs!H4 -> 0.090971722 | I5: =Inputs!I4 -> 0.12075074
A6: Weights | B6: 0.0068065018 | C6: 0.067506952 | D6: 0.080151285 | E6: 0.36373044 | F6: 0.26524288 | G6: 0.20803384 | H6: -0.045604674 | I6: 0.054132779 | J6: =SUM(B6:I6) -> 1
A7: Weighted returns | B7: =B6*B4 -> 6.8109071e-05 | C7: =C6*C4 -> 0.00018861343 | D7: =D6*D4 -> 0.0011333306 | E7: =E6*E4 -> 0.0028175459 | F7: =F6*F4 -> 0.0008717549 | G7: =G6*G4 -> 0.0026862147 | H7: =H6*H4 -> -0.00060267264 | I7: =I6*I4 -> 0.0012393165 | J7: =SUM(B7:I7) -> 0.0084022126
A9: {=Inputs!A22:I30} -> Samle covariance matrix | B9: XOM | C9: GE | D9: HD | E9: JNJ | F9: VZ | G9: WMT | H9: BAC | I9: NFLX
A10: XOM | B10: 0.007153023 | C10: 0.0040423296 | D10: 0.0016739095 | E10: 0.0015096923 | F10: 0.0012158845 | G10: 0.00068937807 | H10: 0.0041741886 | I10: 0.00079406001
A11: GE | B11: 0.0040423296 | C11: 0.011451394 | D11: 0.0015333245 | E11: 0.00032587411 | F11: 0.00068862861 | G11: 0.00048384967 | H11: 0.0050560908 | I11: 0.0042244662
A12: HD | B12: 0.0016739095 | C12: 0.0015333245 | D12: 0.0042014538 | E12: 0.0011223169 | F12: 0.00088362389 | G12: 0.0011779241 | H12: 0.0031122945 | I12: 0.0023283332
A13: JNJ | B13: 0.0015096923 | C13: 0.00032587411 | D13: 0.0011223169 | E13: 0.002154412 | F13: 0.00095276915 | G13: 0.0010734612 | H13: 0.0013542273 | I13: 6.0516346e-05
A14: VZ | B14: 0.0012158845 | C14: 0.00068862861 | D14: 0.00088362389 | E14: 0.00095276915 | F14: 0.0026241756 | G14: 0.00088324802 | H14: 0.00084171328 | I14: 0.00018217928
A15: WMT | B15: 0.00068937807 | C15: 0.00048384967 | D15: 0.0011779241 | E15: 0.0010734612 | F15: 0.00088324802 | G15: 0.0026950499 | H15: 0.00077235706 | I15: 0.00076610459
A16: BAC | B16: 0.0041741886 | C16: 0.0050560908 | D16: 0.0031122945 | E16: 0.0013542273 | F16: 0.00084171328 | G16: 0.00077235706 | H16: 0.0082758541 | I16: 0.0037892337
A17: NFLX | B17: 0.00079406001 | C17: 0.0042244662 | D17: 0.0023283332 | E17: 6.0516346e-05 | F17: 0.00018217928 | G17: 0.00076610459 | H17: 0.0037892337 | I17: 0.014580741
A19: Min Variance Portfolio | B19: Monthly | C19: Annualized
A20: Mu_p | B20: =AVERAGE(J7) -> 0.0084022126 | C20: =B20*12 -> 0.10082655
A21: Sigma_p | B21: =SQRT(B22) -> 0.03637861 | C21: =B21*SQRT(12) -> 0.1260192
A22: Sigma^2_p | B22: {=MMULT(MMULT(B6:I6,B10:I17),TRANSPOSE(B6:I6))} -> 0.0013234032 | C22: =B22*12 -> 0.015880839
A23: Risk free rate | B23: =C23/12 -> 0.0025 | C23: 0.03
A24: Sharpe ratio | B24: =(B20-B23)/B21 -> 0.16224404 | C24: =(C20-C23)/C21 -> 0.56202984
A27: Solver: Minimize monthly variance (B22)

Sheet Best Portfolio No Short Selling
A1: Monthly | I1: n | J1: =COUNTA(B2:I2) -> 8
B2: XOM_avrg | C2: GE_avrg | D2: HD_avrg | E2: JNJ_avrg | F2: VZ_avrg | G2: WMT_avrg | H2: BAC_avrg | I2: NFLX_avrg | J2: Sum
A3: Average montly returns | B3: =Inputs!B3 -> 0.010006472 | C3: =Inputs!C3 -> 0.0027939853 | D3: =Inputs!D3 -> 0.014139894 | E3: =Inputs!E3 -> 0.0077462473 | F3: =Inputs!F3 -> 0.0032866288 | G3: =Inputs!G3 -> 0.012912393 | H3: =Inputs!H3 -> 0.013215151 | I3: =Inputs!I3 -> 0.022894013
A4: Monthly standard deviations (sigma) | B4: =Inputs!B4 -> 0.084575546 | C4: =Inputs!C4 -> 0.10701119 | D4: =Inputs!D4 -> 0.064818623 | E4: =Inputs!E4 -> 0.046415644 | F4: =Inputs!F4 -> 0.051226708 | G4: =Inputs!G4 -> 0.05191387 | H4: =Inputs!H4 -> 0.090971722 | I4: =Inputs!I4 -> 0.12075074
A5: Weights | B5: 0.063202568 | C5: 0 | D5: 0.21850772 | E5: 0.012040632 | F5: 0 | G5: 0.52196553 | H5: 0 | I5: 0.18428355 | J5: =SUM(B5:I5) -> 1
A6: Weighted returns | B6: =B3*B5 -> 0.00063243473 | C6: =C3*C5 -> 0 | D6: =D3*D5 -> 0.003089676 | E6: =E3*E5 -> 9.326971e-05 | F6: =F3*F5 -> 0 | G6: =G3*G5 -> 0.0067398241 | H6: =H3*H5 -> 0 | I6: =I3*I5 -> 0.0042189899 | J6: =SUM(B6:I6) -> 0.014774194
A8: {=Inputs!A22:I30} -> Samle covariance matrix | B8: XOM | C8: GE | D8: HD | E8: JNJ | F8: VZ | G8: WMT | H8: BAC | I8: NFLX
A9: XOM | B9: 0.007153023 | C9: 0.0040423296 | D9: 0.0016739095 | E9: 0.0015096923 | F9: 0.0012158845 | G9: 0.00068937807 | H9: 0.0041741886 | I9: 0.00079406001
A10: GE | B10: 0.0040423296 | C10: 0.011451394 | D10: 0.0015333245 | E10: 0.00032587411 | F10: 0.00068862861 | G10: 0.00048384967 | H10: 0.0050560908 | I10: 0.0042244662
A11: HD | B11: 0.0016739095 | C11: 0.0015333245 | D11: 0.0042014538 | E11: 0.0011223169 | F11: 0.00088362389 | G11: 0.0011779241 | H11: 0.0031122945 | I11: 0.0023283332
A12: JNJ | B12: 0.0015096923 | C12: 0.00032587411 | D12: 0.0011223169 | E12: 0.002154412 | F12: 0.00095276915 | G12: 0.0010734612 | H12: 0.0013542273 | I12: 6.0516346e-05
A13: VZ | B13: 0.0012158845 | C13: 0.00068862861 | D13: 0.00088362389 | E13: 0.00095276915 | F13: 0.0026241756 | G13: 0.00088324802 | H13: 0.00084171328 | I13: 0.00018217928
A14: WMT | B14: 0.00068937807 | C14: 0.00048384967 | D14: 0.0011779241 | E14: 0.0010734612 | F14: 0.00088324802 | G14: 0.0026950499 | H14: 0.00077235706 | I14: 0.00076610459
A15: BAC | B15: 0.0041741886 | C15: 0.0050560908 | D15: 0.0031122945 | E15: 0.0013542273 | F15: 0.00084171328 | G15: 0.00077235706 | H15: 0.0082758541 | I15: 0.0037892337
A16: NFLX | B16: 0.00079406001 | C16: 0.0042244662 | D16: 0.0023283332 | E16: 6.0516346e-05 | F16: 0.00018217928 | G16: 0.00076610459 | H16: 0.0037892337 | I16: 0.014580741
A18: Best Portfolio No Short Selling | B18: Monthly | C18: Annualized
A19: Mu_p | B19: =AVERAGE(J6) -> 0.014774194 | C19: =B19*12 -> 0.17729033 | G19: 0 | H19: 1 | I19: 2 | J19: 3
A20: Sigma_p | B20: =SQRT(B21) -> 0.046847451 | C20: =B20*SQRT(12) -> 0.16228433 | G20: =C19 -> 0.17729033 | H20: =C19+C20 -> 0.33957466 | I20: =H20+C20 -> 0.501859 | J20: =I20+C20 -> 0.66414333
A21: Sigma^2_p | B21: {=MMULT(MMULT(B5:I5,B9:I16),TRANSPOSE(B5:I5))} -> 0.0021946837 | C21: =B21*12 -> 0.026336204 | G21: 0.5 | H21: 0.6827 | I21: 0.9545 | J21: 0.9973
A22: Risk free rate | B22: =C22/12 -> 0.0025 | C22: 0.03
A23: Sharpe ratio | B23: =(B19-B22)/B20 -> 0.26200346 | C23: =(C19-C22)/C20 -> 0.90760663
A26: Solver: Maximize monthly sharpe ratio (B23)
A27: Non-negative values only
A30: Exxon Mobil Corp | B30: General Electric | C30: Home Depot Inc | D30: Johnson & Johnson | E30: Verizon Communications Inc | F30: Walmart Inc | G30: Bank of America Corp | H30: Netflix

Sheet Best Portfolio, weights<20%
A1: Monthly | I1: n | J1: =COUNTA(B2:I2) -> 8
B2: XOM_avrg | C2: GE_avrg | D2: HD_avrg | E2: JNJ_avrg | F2: VZ_avrg | G2: WMT_avrg | H2: BAC_avrg | I2: NFLX_avrg | J2: Sum
A3: Avarage montly returns | B3: =Inputs!B3 -> 0.010006472 | C3: =Inputs!C3 -> 0.0027939853 | D3: =Inputs!D3 -> 0.014139894 | E3: =Inputs!E3 -> 0.0077462473 | F3: =Inputs!F3 -> 0.0032866288 | G3: =Inputs!G3 -> 0.012912393 | H3: =Inputs!H3 -> 0.013215151 | I3: =Inputs!I3 -> 0.022894013
A4: Monthly standard deviations (sigma) | B4: =Inputs!B4 -> 0.084575546 | C4: =Inputs!C4 -> 0.10701119 | D4: =Inputs!D4 -> 0.064818623 | E4: =Inputs!E4 -> 0.046415644 | F4: =Inputs!F4 -> 0.051226708 | G4: =Inputs!G4 -> 0.05191387 | H4: =Inputs!H4 -> 0.090971722 | I4: =Inputs!I4 -> 0.12075074
A5: Weights | B5: 0.19487152 | C5: -0.16873598 | D5: 0.2 | E5: 0.2 | F5: 0.048063445 | G5: 0.2 | H5: 0.12580103 | I5: 0.2 | J5: =SUM(B5:I5) -> 1
A6: Weighted returns | B6: =B3*B5 -> 0.0019499764 | C6: =C3*C5 -> -0.00047144584 | D6: =D3*D5 -> 0.0028279787 | E6: =E3*E5 -> 0.0015492495 | F6: =F3*F5 -> 0.00015796671 | G6: =G3*G5 -> 0.0025824786 | H6: =H3*H5 -> 0.0016624795 | I6: =I3*I5 -> 0.0045788026 | J6: =SUM(B6:I6) -> 0.014837486
A8: {=Inputs!A22:I30} -> Samle covariance matrix | B8: XOM | C8: GE | D8: HD | E8: JNJ | F8: VZ | G8: WMT | H8: BAC | I8: NFLX
A9: XOM | B9: 0.007153023 | C9: 0.0040423296 | D9: 0.0016739095 | E9: 0.0015096923 | F9: 0.0012158845 | G9: 0.00068937807 | H9: 0.0041741886 | I9: 0.00079406001
A10: GE | B10: 0.0040423296 | C10: 0.011451394 | D10: 0.0015333245 | E10: 0.00032587411 | F10: 0.00068862861 | G10: 0.00048384967 | H10: 0.0050560908 | I10: 0.0042244662
A11: HD | B11: 0.0016739095 | C11: 0.0015333245 | D11: 0.0042014538 | E11: 0.0011223169 | F11: 0.00088362389 | G11: 0.0011779241 | H11: 0.0031122945 | I11: 0.0023283332
A12: JNJ | B12: 0.0015096923 | C12: 0.00032587411 | D12: 0.0011223169 | E12: 0.002154412 | F12: 0.00095276915 | G12: 0.0010734612 | H12: 0.0013542273 | I12: 6.0516346e-05
A13: VZ | B13: 0.0012158845 | C13: 0.00068862861 | D13: 0.00088362389 | E13: 0.00095276915 | F13: 0.0026241756 | G13: 0.00088324802 | H13: 0.00084171328 | I13: 0.00018217928
A14: WMT | B14: 0.00068937807 | C14: 0.00048384967 | D14: 0.0011779241 | E14: 0.0010734612 | F14: 0.00088324802 | G14: 0.0026950499 | H14: 0.00077235706 | I14: 0.00076610459
A15: BAC | B15: 0.0041741886 | C15: 0.0050560908 | D15: 0.0031122945 | E15: 0.0013542273 | F15: 0.00084171328 | G15: 0.00077235706 | H15: 0.0082758541 | I15: 0.0037892337
A16: NFLX | B16: 0.00079406001 | C16: 0.0042244662 | D16: 0.0023283332 | E16: 6.0516346e-05 | F16: 0.00018217928 | G16: 0.00076610459 | H16: 0.0037892337 | I16: 0.014580741
A18: Best Portfolio, weights<20% | B18: Monthly | C18: Annualized
A19: Mu_p | B19: =AVERAGE(J6) -> 0.014837486 | C19: =B19*12 -> 0.17804984
A20: Sigma_p | B20: =SQRT(B21) -> 0.048773272 | C20: =B20*SQRT(12) -> 0.16895557
A21: Sigma^2_p | B21: {=MMULT(MMULT(B5:I5,B9:I16),TRANSPOSE(B5:I5))} -> 0.0023788321 | C21: =B21*12 -> 0.028545985
A22: Risk free rate | B22: =C22/12 -> 0.0025 | C22: 0.03
A23: Sharpe ratio | B23: =(B19-B22)/B20 -> 0.25295589 | C23: =(C19-C22)/C20 -> 0.8762649
A26: Solver: Maximize monthly sharpe ratio (B23)
A27: Restrictions: each weight cannot be lower than-20% or higher than 20%.

Sheet Best Portfolio, sigma=market
A1: Monthly | J1: n | K1: =COUNTA(B2:I2) -> 8
B2: XOM_avrg | C2: GE_avrg | D2: HD_avrg | E2: JNJ_avrg | F2: VZ_avrg | G2: WMT_avrg | H2: BAC_avrg | I2: NFLX_avrg | J2: Market | K2: Sum
A3: Average montly returns | B3: =Inputs!B3 -> 0.010006472 | C3: =Inputs!C3 -> 0.0027939853 | D3: =Inputs!D3 -> 0.014139894 | E3: =Inputs!E3 -> 0.0077462473 | F3: =Inputs!F3 -> 0.0032866288 | G3: =Inputs!G3 -> 0.012912393 | H3: =Inputs!H3 -> 0.013215151 | I3: =Inputs!I3 -> 0.022894013
A4: Monthly standard deviations (sigma) | B4: =Inputs!B4 -> 0.084575546 | C4: =Inputs!C4 -> 0.10701119 | D4: =Inputs!D4 -> 0.064818623 | E4: =Inputs!E4 -> 0.046415644 | F4: =Inputs!F4 -> 0.051226708 | G4: =Inputs!G4 -> 0.05191387 | H4: =Inputs!H4 -> 0.090971722 | I4: =Inputs!I4 -> 0.12075074 | J4: =_xlfn.STDEV.S(Data!K2:K97) -> 0.046344002
A5: Weights | B5: 0.12693997 | C5: -0.10350985 | D5: 0.18953871 | E5: 0.17991923 | F5: -0.070325488 | G5: 0.4931349 | H5: 0.010681346 | I5: 0.17362118 | K5: =SUM(B5:I5) -> 1
A6: Weighted returns | B6: =B3*B5 -> 0.0012702213 | C6: =C3*C5 -> -0.000289205 | D6: =D3*D5 -> 0.0026800572 | E6: =E3*E5 -> 0.0013936989 | F6: =F3*F5 -> -0.00023113378 | G6: =G3*G5 -> 0.0063675517 | H6: =H3*H5 -> 0.0001411556 | I6: =I3*I5 -> 0.0039748855 | K6: =SUM(B6:I6) -> 0.015307231
A8: {=Inputs!A22:I30} -> Samle covariance matrix | B8: XOM | C8: GE | D8: HD | E8: JNJ | F8: VZ | G8: WMT | H8: BAC | I8: NFLX
A9: XOM | B9: 0.007153023 | C9: 0.0040423296 | D9: 0.0016739095 | E9: 0.0015096923 | F9: 0.0012158845 | G9: 0.00068937807 | H9: 0.0041741886 | I9: 0.00079406001
A10: GE | B10: 0.0040423296 | C10: 0.011451394 | D10: 0.0015333245 | E10: 0.00032587411 | F10: 0.00068862861 | G10: 0.00048384967 | H10: 0.0050560908 | I10: 0.0042244662
A11: HD | B11: 0.0016739095 | C11: 0.0015333245 | D11: 0.0042014538 | E11: 0.0011223169 | F11: 0.00088362389 | G11: 0.0011779241 | H11: 0.0031122945 | I11: 0.0023283332
A12: JNJ | B12: 0.0015096923 | C12: 0.00032587411 | D12: 0.0011223169 | E12: 0.002154412 | F12: 0.00095276915 | G12: 0.0010734612 | H12: 0.0013542273 | I12: 6.0516346e-05
A13: VZ | B13: 0.0012158845 | C13: 0.00068862861 | D13: 0.00088362389 | E13: 0.00095276915 | F13: 0.0026241756 | G13: 0.00088324802 | H13: 0.00084171328 | I13: 0.00018217928
A14: WMT | B14: 0.00068937807 | C14: 0.00048384967 | D14: 0.0011779241 | E14: 0.0010734612 | F14: 0.00088324802 | G14: 0.0026950499 | H14: 0.00077235706 | I14: 0.00076610459
A15: BAC | B15: 0.0041741886 | C15: 0.0050560908 | D15: 0.0031122945 | E15: 0.0013542273 | F15: 0.00084171328 | G15: 0.00077235706 | H15: 0.0082758541 | I15: 0.0037892337
A16: NFLX | B16: 0.00079406001 | C16: 0.0042244662 | D16: 0.0023283332 | E16: 6.0516346e-05 | F16: 0.00018217928 | G16: 0.00076610459 | H16: 0.0037892337 | I16: 0.014580741
A18: Best Portfolio, sigma=market | B18: Monthly | C18: Annualized
A19: Mu_p | B19: =K6 -> 0.015307231 | C19: =B19*12 -> 0.18368678
A20: Sigma_p | B20: =SQRT(B21) -> 0.046344002 | C20: =B20*SQRT(12) -> 0.16054033
A21: Sigma^2_p | B21: {=MMULT(MMULT(B5:I5,B9:I16),TRANSPOSE(B5:I5))} -> 0.0021477665 | C21: =B21*12 -> 0.025773198
A22: Risk free rate | B22: =C22/12 -> 0.0025 | C22: 0.03
A23: Sharpe ratio | B23: =(B19-B22)/B20 -> 0.27635143 | C23: =(C19-C22)/C20 -> 0.95730945
A26: Solver: Maximize monthly sharpe ratio (B23)
A27: Restrictions: sigma_p = sigma_m (B20 = J4)

Sheet Best Portfolio
A1: Monthly | I1: n | J1: =COUNTA(B2:I2) -> 8
B2: XOM_avrg | C2: GE_avrg | D2: HD_avrg | E2: JNJ_avrg | F2: VZ_avrg | G2: WMT_avrg | H2: BAC_avrg | I2: NFLX_avrg | J2: Sum
A3: Avarage montly returns | B3: =Inputs!B3 -> 0.010006472 | C3: =Inputs!C3 -> 0.0027939853 | D3: =Inputs!D3 -> 0.014139894 | E3: =Inputs!E3 -> 0.0077462473 | F3: =Inputs!F3 -> 0.0032866288 | G3: =Inputs!G3 -> 0.012912393 | H3: =Inputs!H3 -> 0.013215151 | I3: =Inputs!I3 -> 0.022894013
A4: Monthly standard deviations (sigma) | B4: =Inputs!B4 -> 0.084575546 | C4: =Inputs!C4 -> 0.10701119 | D4: =Inputs!D4 -> 0.064818623 | E4: =Inputs!E4 -> 0.046415644 | F4: =Inputs!F4 -> 0.051226708 | G4: =Inputs!G4 -> 0.05191387 | H4: =Inputs!H4 -> 0.090971722 | I4: =Inputs!I4 -> 0.12075074
A5: Weights | B5: 0.23403736 | C5: -0.25274876 | D5: 0.28807917 | E5: 0.01929543 | F5: -0.36608381 | G5: 0.74297782 | H5: 0.055245281 | I5: 0.27919751 | J5: =SUM(B5:I5) -> 1
A6: Weighted returns | B6: =B3*B5 -> 0.0023418884 | C6: =C3*C5 -> -0.00070617632 | D6: =D3*D5 -> 0.0040734088 | E6: =E3*E5 -> 0.00014946717 | F6: =F3*F5 -> -0.0012031816 | G6: =G3*G5 -> 0.0095936217 | H6: =H3*H5 -> 0.00073007472 | I6: =I3*I5 -> 0.0063919514 | J6: =SUM(B6:I6) -> 0.021371054
A8: {=Inputs!A22:I30} -> Samle covariance matrix | B8: XOM | C8: GE | D8: HD | E8: JNJ | F8: VZ | G8: WMT | H8: BAC | I8: NFLX
A9: XOM | B9: 0.007153023 | C9: 0.0040423296 | D9: 0.0016739095 | E9: 0.0015096923 | F9: 0.0012158845 | G9: 0.00068937807 | H9: 0.0041741886 | I9: 0.00079406001
A10: GE | B10: 0.0040423296 | C10: 0.011451394 | D10: 0.0015333245 | E10: 0.00032587411 | F10: 0.00068862861 | G10: 0.00048384967 | H10: 0.0050560908 | I10: 0.0042244662
A11: HD | B11: 0.0016739095 | C11: 0.0015333245 | D11: 0.0042014538 | E11: 0.0011223169 | F11: 0.00088362389 | G11: 0.0011779241 | H11: 0.0031122945 | I11: 0.0023283332
A12: JNJ | B12: 0.0015096923 | C12: 0.00032587411 | D12: 0.0011223169 | E12: 0.002154412 | F12: 0.00095276915 | G12: 0.0010734612 | H12: 0.0013542273 | I12: 6.0516346e-05
A13: VZ | B13: 0.0012158845 | C13: 0.00068862861 | D13: 0.00088362389 | E13: 0.00095276915 | F13: 0.0026241756 | G13: 0.00088324802 | H13: 0.00084171328 | I13: 0.00018217928
A14: WMT | B14: 0.00068937807 | C14: 0.00048384967 | D14: 0.0011779241 | E14: 0.0010734612 | F14: 0.00088324802 | G14: 0.0026950499 | H14: 0.00077235706 | I14: 0.00076610459
A15: BAC | B15: 0.0041741886 | C15: 0.0050560908 | D15: 0.0031122945 | E15: 0.0013542273 | F15: 0.00084171328 | G15: 0.00077235706 | H15: 0.0082758541 | I15: 0.0037892337
A16: NFLX | B16: 0.00079406001 | C16: 0.0042244662 | D16: 0.0023283332 | E16: 6.0516346e-05 | F16: 0.00018217928 | G16: 0.00076610459 | H16: 0.0037892337 | I16: 0.014580741
A18: Best Portfolio | B18: Monthly | C18: Annualized
A19: Mu_p | B19: =AVERAGE(J6) -> 0.021371054 | C19: =B19*12 -> 0.25645265
A20: Sigma_p | B20: =SQRT(B21) -> 0.065048381 | C20: =B20*SQRT(12) -> 0.2253342
A21: Sigma^2_p | B21: {=MMULT(MMULT(B5:I5,B9:I16),TRANSPOSE(B5:I5))} -> 0.0042312919 | C21: =B21*12 -> 0.050775503
A22: Risk free rate | B22: =C22/12 -> 0.0025 | C22: 0.03
A23: Sharpe ratio | B23: =(B19-B22)/B20 -> 0.29010798 | C23: =(C19-C22)/C20 -> 1.0049635
A26: Solver: Maximize monthly sharpe ratio (B23)

Sheet Plot Returns_Risk2
A1: Annualized | B1: XOM | C1: GE | D1: HD | E1: JNJ | F1: VZ | G1: WMT | H1: BAC | I1: NFLX | J1: Market | K1: MVP | L1: Best portfolio
A2: Mu_p | B2: =Inputs!B5 -> 0.12007767 | C2: =Inputs!C5 -> 0.033527823 | D2: =Inputs!D5 -> 0.16967872 | E2: =Inputs!E5 -> 0.092954968 | F2: =Inputs!F5 -> 0.039439546 | G2: =Inputs!G5 -> 0.15494872 | H2: =Inputs!H5 -> 0.15858181 | I2: =Inputs!I5 -> 0.27472816 | J2: =AVERAGE(Data!K2:K97)*12 -> 0.11922758 | K2: ='Min Variance Portfolio'!C20 -> 0.10082655 | L2: ='Best Portfolio'!C19 -> 0.25645265
A3: Sigma_p | B3: =Inputs!B6 -> 0.29297829 | C3: =Inputs!C6 -> 0.37069763 | D3: =Inputs!D6 -> 0.2245383 | E3: =Inputs!E6 -> 0.16078851 | F3: =Inputs!F6 -> 0.17745452 | G3: =Inputs!G6 -> 0.17983492 | H3: =Inputs!H6 -> 0.31513529 | I3: =Inputs!I6 -> 0.41829283 | J3: =_xlfn.STDEV.S(Data!K2:K97)*SQRT(12) -> 0.16054033 | K3: ='Min Variance Portfolio'!C21 -> 0.1260192 | L3: ='Best Portfolio'!C20 -> 0.2253342

Sheet Sheet1
I1: Weights
B2: Mu_p | C2: Sigma_p | D2: Sigma^2_p | E2: Risk free rate | F2: Sharpe ratio | H2: Stocks | I2: Exxon Mobil Corp | J2: General Electric | K2: Home Depot Inc | L2: Johnson & Johnson | M2: Verizon Communications Inc | N2: Walmart Inc | O2: Bank of America Corp | P2: Netflix
A3: EW Portfolio | B3: 0.13049218 | C3: 0.164636 | E3: 0.03 | F3: 0.61039006 | H3: EW Portfolio | I3: 0.125 | J3: 0.125 | K3: 0.125 | L3: 0.125 | M3: 0.125 | N3: 0.125 | O3: 0.125 | P3: 0.125
A4: Min Variance Portfolio | B4: 0.10082655 | C4: 0.1260192 | D4: 0.015880839 | E4: 0.03 | F4: 0.56202984 | H4: Min Variance Portfolio | I4: 0.0068065018 | J4: 0.067506952 | K4: 0.080151285 | L4: 0.36373044 | M4: 0.26524288 | N4: 0.20803384 | O4: -0.045604674 | P4: 0.054132779
A5: Best Portfolio No Short Selling | B5: 0.17729033 | C5: 0.16228433 | D5: 0.026336204 | E5: 0.03 | F5: 0.90760663 | H5: Best Portfolio No Short Selling | I5: 0.063202568 | J5: 0 | K5: 0.21850772 | L5: 0.012040632 | M5: 0 | N5: 0.52196553 | O5: 0 | P5: 0.18428355
A6: Best Portfolio, weights<20% | B6: 0.17804984 | C6: 0.16895557 | D6: 0.028545985 | E6: 0.03 | F6: 0.8762649 | H6: Best Portfolio, weights<20% | I6: 0.19487152 | J6: -0.16873598 | K6: 0.2 | L6: 0.2 | M6: 0.048063445 | N6: 0.2 | O6: 0.12580103 | P6: 0.2
A7: Best Portfolio, sigma=market | B7: 0.18368678 | C7: 0.16054033 | D7: 0.025773198 | E7: 0.03 | F7: 0.95730945 | H7: Best Portfolio, sigma=market | I7: 0.12693997 | J7: -0.10350985 | K7: 0.18953871 | L7: 0.17991923 | M7: -0.070325488 | N7: 0.4931349 | O7: 0.010681346 | P7: 0.17362118
A8: Best Portfolio | B8: 0.25645265 | C8: 0.2253342 | D8: 0.050775503 | E8: 0.03 | F8: 1.0049635 | H8: Best Portfolio | I8: 0.23403736 | J8: -0.25274876 | K8: 0.28807917 | L8: 0.01929543 | M8: -0.36608381 | N8: 0.74297782 | O8: 0.055245281 | P8: 0.27919751
H9: Stocks | I9: Exxon Mobil Corp | J9: General Electric | K9: Home Depot Inc | L9: Johnson & Johnson | M9: Verizon Communications Inc | N9: Walmart Inc | O9: Bank of America Corp | P9: Netflix
H10: Ticker | I10: XOM | J10: GE | K10: HD | L10: JNJ | M10: VZ | N10: WMT | O10: BAC | P10: NFLX

Sheet SIM-Data
A1: Excess return
A3: Date | B3: XOM_rf | C3: GE_rf | D3: HD_rf | E3: JNJ_rf | F3: VZ_rf | G3: WMT_rf | H3: BAC_rf | I3: NFLX_rf | J3: Market_rf
A5: 42398 | B5: =Data!B2-Data!$J2 -> -0.0013828541 | C5: =Data!C2-Data!$J2 -> -0.065910569 | D5: =Data!D2-Data!$J2 -> -0.049173707 | E5: =Data!E2-Data!$J2 -> 0.01664456 | F5: =Data!F2-Data!$J2 -> 0.093257854 | G5: =Data!G2-Data!$J2 -> 0.082444886 | H5: =Data!H2-Data!$J2 -> -0.15993361 | I5: =Data!I2-Data!$J2 -> -0.19716243 | J5: =Data!K2-Data!$J2 -> -0.05083534
A6: 42429 | B6: =Data!B3-Data!$J3 -> 0.038721043 | C6: =Data!C3-Data!$J3 -> 0.0090783161 | D6: =Data!D3-Data!$J3 -> -0.013240707 | E6: =Data!E3-Data!$J3 -> 0.014353778 | F6: =Data!F3-Data!$J3 -> 0.015009092 | G6: =Data!G3-Data!$J3 -> -0.00050145075 | H6: =Data!H3-Data!$J3 -> -0.11476859 | I6: =Data!I3-Data!$J3 -> 0.016895027 | J6: =Data!K3-Data!$J3 -> -0.004328355
A7: 42460 | B7: =Data!B4-Data!$J4 -> 0.042719461 | C7: =Data!C4-Data!$J4 -> 0.090740341 | D7: =Data!D4-Data!$J4 -> 0.080367107 | E7: =Data!E4-Data!$J4 -> 0.028219333 | F7: =Data!F4-Data!$J4 -> 0.065835919 | G7: =Data!G4-Data!$J4 -> 0.039745759 | H7: =Data!H4-Data!$J4 -> 0.083665814 | I7: =Data!I4-Data!$J4 -> 0.09422243 | J7: =Data!K4-Data!$J4 -> 0.06579111
A8: 42489 | B8: =Data!B5-Data!$J5 -> 0.057442834 | C8: =Data!C5-Data!$J5 -> -0.032814717 | D8: =Data!D5-Data!$J5 -> 0.003347551 | E8: =Data!E5-Data!$J5 -> 0.035759566 | F8: =Data!F5-Data!$J5 -> -0.047714701 | G8: =Data!G5-Data!$J5 -> -0.023753017 | H8: =Data!H5-Data!$J5 -> 0.076823072 | I8: =Data!I5-Data!$J5 -> -0.11943879 | J8: =Data!K5-Data!$J5 -> 0.00259937
A9: 42521 | B9: =Data!B6-Data!$J6 -> 0.015397682 | C9: =Data!C6-Data!$J6 -> -0.017010585 | D9: =Data!D6-Data!$J6 -> -0.0081663553 | E9: =Data!E6-Data!$J6 -> 0.012480305 | F9: =Data!F6-Data!$J6 -> -0.00088518066 | G9: =Data!G6-Data!$J6 -> 0.065848792 | H9: =Data!H6-Data!$J6 -> 0.015696671 | I9: =Data!I6-Data!$J6 -> 0.13918692 | J9: =Data!K6-Data!$J6 -> 0.01522949
A10: 42551 | B10: =Data!B7-Data!$J7 -> 0.052821807 | C10: =Data!C7-Data!$J7 -> 0.048757989 | D10: =Data!D7-Data!$J7 -> -0.033730071 | E10: =Data!E7-Data!$J7 -> 0.076204296 | F10: =Data!F7-Data!$J7 -> 0.096853014 | G10: =Data!G7-Data!$J7 -> 0.031447328 | H10: =Data!H7-Data!$J7 -> -0.099591446 | I10: =Data!I7-Data!$J7 -> -0.10832125 | J10: =Data!K7-Data!$J7 -> 0.0007060735
A11: 42580 | B11: =Data!B8-Data!$J8 -> -0.051298794 | C11: =Data!C8-Data!$J8 -> -0.011000513 | D11: =Data!D8-Data!$J8 -> 0.082421999 | E11: =Data!E8-Data!$J8 -> 0.032199014 | F11: =Data!F8-Data!$J8 -> 0.0022176163 | G11: =Data!G8-Data!$J8 -> -0.00088468123 | H11: =Data!H8-Data!$J8 -> 0.091736648 | I11: =Data!I8-Data!$J8 -> -0.0027142473 | J11: =Data!K8-Data!$J8 -> 0.03540981
A12: 42613 | B12: =Data!B9-Data!$J9 -> -0.01211678 | C12: =Data!C9-Data!$J9 -> 0.0030113162 | D12: =Data!D9-Data!$J9 -> -0.025011996 | E12: =Data!E9-Data!$J9 -> -0.040845268 | F12: =Data!F9-Data!$J9 -> -0.0557856 | G12: =Data!G9-Data!$J9 -> -0.014315373 | H12: =Data!H9-Data!$J9 -> 0.1188476 | I12: =Data!I9-Data!$J9 -> 0.067745175 | J12: =Data!K9-Data!$J9 -> -0.001419176
A13: 42643 | B13: =Data!B10-Data!$J10 -> 0.001406603 | C13: =Data!C10-Data!$J10 -> -0.044694204 | D13: =Data!D10-Data!$J10 -> -0.040760711 | E13: =Data!E10-Data!$J10 -> -0.010339091 | F13: =Data!F10-Data!$J10 -> -0.0068883676 | G13: =Data!G10-Data!$J10 -> 0.0093184809 | H13: =Data!H10-Data!$J10 -> -0.030559343 | I13: =Data!I10-Data!$J10 -> 0.011087902 | J13: =Data!K10-Data!$J10 -> -0.001434483
A14: 42674 | B14: =Data!B11-Data!$J11 -> -0.045571208 | C14: =Data!C11-Data!$J11 -> -0.017755721 | D14: =Data!D11-Data!$J11 -> -0.052033935 | E14: =Data!E11-Data!$J11 -> -0.01831563 | F14: =Data!F11-Data!$J11 -> -0.063734074 | G14: =Data!G11-Data!$J11 -> -0.029318219 | H14: =Data!H11-Data!$J11 -> 0.054113123 | I14: =Data!I11-Data!$J11 -> 0.26687253 | J14: =Data!K11-Data!$J11 -> -0.01962562
A15: 42704 | B15: =Data!B12-Data!$J12 -> 0.056669125 | C15: =Data!C12-Data!$J12 -> 0.056944666 | D15: =Data!D12-Data!$J12 -> 0.066124009 | E15: =Data!E12-Data!$J12 -> -0.033637328 | F15: =Data!F12-Data!$J12 -> 0.037322102 | G15: =Data!G12-Data!$J12 -> 0.0057555226 | H15: =Data!H12-Data!$J12 -> 0.28444551 | I15: =Data!I12-Data!$J12 -> -0.063125564 | J15: =Data!K12-Data!$J12 -> 0.03407445
A16: 42734 | B16: =Data!B13-Data!$J13 -> 0.033606061 | C16: =Data!C13-Data!$J13 -> 0.034810537 | D16: =Data!D13-Data!$J13 -> 0.035866988 | E16: =Data!E13-Data!$J13 -> 0.034830244 | F16: =Data!F13-Data!$J13 -> 0.069439468 | G16: =Data!G13-Data!$J13 -> -0.011800746 | H16: =Data!H13-Data!$J13 -> 0.046101493 | I16: =Data!I13-Data!$J13 -> 0.057819684 | J16: =Data!K13-Data!$J13 -> 0.01790075
... A100: 45289 | B100: =Data!B97-Data!$J97 -> -0.031163875 | C100: =Data!C97-Data!$J97 -> 0.044222118 | D100: =Data!D97-Data!$J97 -> 0.1011579 | E100: =Data!E97-Data!$J97 -> 0.009148867 | F100: =Data!F97-Data!$J97 -> -0.02073624 | G100: =Data!G97-Data!$J97 -> 0.011950186 | H100: =Data!H97-Data!$J97 -> 0.099996438 | I100: =Data!I97-Data!$J97 -> 0.022938019 | J100: =Data!K97-Data!$J97 -> 0.03992917

Sheet Sim_Regressions
A1: XOM_rf
A3: Regression Statistics
A4: Multiple R | B4: 0.52983431
A5: R Square | B5: 0.2807244
A6: Adjusted R Square | B6: 0.27307253
A7: Standard Error | B7: 0.072282484
A8: Observations | B8: 96
A10: ANOVA
B11: df | C11: SS | D11: MS | E11: F | F11: Significance F
A12: Regression | B12: 1 | C12: 0.19168089 | D12: 0.19168089 | E12: 36.687041 | F12: 2.839512e-08
A13: Residual | B13: 94 | C13: 0.4911272 | D13: 0.0052247575
A14: Total | B14: 95 | C14: 0.6828081
B16: Coefficients | C16: Standard Error | D16: t Stat | E16: P-value | F16: Lower 95% | G16: Upper 95% | H16: Lower 95,0% | I16: Upper 95,0%
A17: Intercept | B17: 0.00034746324 | C17: 0.0075078792 | D17: 0.046279812 | E17: 0.96318541 | F17: -0.014559607 | G17: 0.015254533 | H17: -0.014559607 | I17: 0.015254533
A18: Market_rf | B18: 0.96828099 | C18: 0.15986193 | D18: 6.0569829 | E18: 2.839512e-08 | F18: 0.65087137 | G18: 1.2856906 | H18: 0.65087137 | I18: 1.2856906
A21: GE_rf
A23: Regression Statistics
A24: Multiple R | B24: 0.52620884
A25: R Square | B25: 0.27689574
A26: Adjusted R Square | B26: 0.26920314
A27: Standard Error | B27: 0.091312553
A28: Observations | B28: 96
A30: ANOVA
B31: df | C31: SS | D31: MS | E31: F | F31: Significance F
A32: Regression | B32: 1 | C32: 0.30012639 | D32: 0.30012639 | E32: 35.995086 | F32: 3.6676711e-08
A33: Residual | B33: 94 | C33: 0.78377034 | D33: 0.0083379823
A34: Total | B34: 95 | C34: 1.0838967
B36: Coefficients | C36: Standard Error | D36: t Stat | E36: P-value | F36: Lower 95% | G36: Upper 95% | H36: Lower 95,0% | I36: Upper 95,0%
A37: Intercept | B37: -0.0089871378 | C37: 0.0094845055 | D37: -0.94755998 | E37: 0.34578313 | F37: -0.027818846 | G37: 0.0098445701 | H37: -0.027818846 | I37: 0.0098445701
A38: Market_rf | B38: 1.2116134 | C38: 0.20194936 | D38: 5.9995905 | E38: 3.6676711e-08 | F38: 0.81063826 | G38: 1.6125886 | H38: 0.81063826 | I38: 1.6125886
A41: HD_rf
A43: Regression Statistics
A44: Multiple R | B44: 0.73440795
A45: R Square | B45: 0.53935504
A46: Adjusted R Square | B46: 0.53445456
A47: Standard Error | B47: 0.044252582
A48: Observations | B48: 96
A50: ANOVA
B51: df | C51: SS | D51: MS | E51: F | F51: Significance F
A52: Regression | B52: 1 | C52: 0.21553286 | D52: 0.21553286 | E52: 110.06171 | F52: 1.6700053e-17
...

Sheet SIM-Inputs
B1: XOM_rf | C1: GE_rf | D1: HD_rf | E1: JNJ_rf | F1: VZ_rf | G1: WMT_rf | H1: BAC_rf | I1: NFLX_rf | J1: Market
A3: Alpha | B3: =Sim_Regressions!B17 -> 0.00034746324 | C3: =Sim_Regressions!B37 -> -0.0089871378 | D3: =Sim_Regressions!B57 -> 0.0039708906 | E3: =Sim_Regressions!B77 -> 0.0017693582 | F3: =Sim_Regressions!B97 -> -0.0014066213 | G3: =Sim_Regressions!B117 -> 0.0074872101 | H3: =Sim_Regressions!B137 -> -0.0006420251 | I3: =Sim_Regressions!B157 -> 0.010326954 | J3: 0
A4: Beta | B4: =Sim_Regressions!B18 -> 0.96828099 | C4: =Sim_Regressions!B38 -> 1.2116134 | D4: =Sim_Regressions!B58 -> 1.0267595 | E4: =Sim_Regressions!B78 -> 0.54607031 | F4: =Sim_Regressions!B98 -> 0.39888171 | G4: =Sim_Regressions!B118 -> 0.48280888 | H4: =Sim_Regressions!B138 -> 1.4496643 | I4: =Sim_Regressions!B158 -> 1.3017329 | J4: 1
A5: Idiosyncratic volatility | B5: =Sim_Regressions!B7 -> 0.072282484 | C5: =Sim_Regressions!B27 -> 0.091312553 | D5: =Sim_Regressions!B47 -> 0.044252582 | E5: =Sim_Regressions!B67 -> 0.039349004 | F5: =Sim_Regressions!B87 -> 0.048017357 | G5: =Sim_Regressions!B107 -> 0.047099282 | H5: =Sim_Regressions!B127 -> 0.061744302 | I5: =Sim_Regressions!B147 -> 0.10495369 | J5: 0
A6: Sigma | J6: =_xlfn.STDEV.S('SIM-Data'!J5:J100) -> 0.046390196
A7: Risk premium | J7: =AVERAGE('SIM-Data'!J5:J100) -> 0.0087210487
B13: Exxon Mobil Corp | C13: General Electric | D13: Home Depot Inc | E13: Johnson & Johnson | F13: Verizon Communications Inc | G13: Walmart Inc | H13: Bank of America Corp | I13: Netflix | J13: Market
A14: Alpha | B14: =Sim_Regressions!B17 -> 0.00034746324 | C14: =Sim_Regressions!B37 -> -0.0089871378 | D14: =Sim_Regressions!B57 -> 0.0039708906 | E14: =Sim_Regressions!B77 -> 0.0017693582 | F14: =Sim_Regressions!B97 -> -0.0014066213 | G14: =Sim_Regressions!B117 -> 0.0074872101 | H14: =Sim_Regressions!B137 -> -0.0006420251 | I14: =Sim_Regressions!B157 -> 0.010326954 | J14: 0
A15: Beta | B15: =Sim_Regressions!B18 -> 0.96828099 | C15: =Sim_Regressions!B38 -> 1.2116134 | D15: =Sim_Regressions!B58 -> 1.0267595 | E15: =Sim_Regressions!B78 -> 0.54607031 | F15: =Sim_Regressions!B98 -> 0.39888171 | G15: =Sim_Regressions!B118 -> 0.48280888 | H15: =Sim_Regressions!B138 -> 1.4496643 | I15: =Sim_Regressions!B158 -> 1.3017329 | J15: 1
A16: Idiosyncratic volatility | B16: =Sim_Regressions!B7 -> 0.072282484 | C16: =Sim_Regressions!B27 -> 0.091312553 | D16: =Sim_Regressions!B47 -> 0.044252582 | E16: =Sim_Regressions!B67 -> 0.039349004 | F16: =Sim_Regressions!B87 -> 0.048017357 | G16: =Sim_Regressions!B107 -> 0.047099282 | H16: =Sim_Regressions!B127 -> 0.061744302 | I16: =Sim_Regressions!B147 -> 0.10495369 | J16: 0
A17: Sigma | J17: =_xlfn.STDEV.S('SIM-Data'!J16:J111) -> 0.048175928
A18: Risk premium | J18: =AVERAGE('SIM-Data'!J16:J111) -> 0.0089535687

Sheet SIM-Results
B1: XOM_rf | C1: GE_rf | D1: HD_rf | E1: JNJ_rf | F1: VZ_rf | G1: WMT_rf | H1: BAC_rf | I1: NFLX_rf | J1: Market | K1: Total | L1: n | M1: =COUNTA(B3:J3) -> 9
A3: Alpha | B3: =Sim_Regressions!B17 -> 0.00034746324 | C3: =Sim_Regressions!B37 -> -0.0089871378 | D3: =Sim_Regressions!B57 -> 0.0039708906 | E3: =Sim_Regressions!B77 -> 0.0017693582 | F3: =Sim_Regressions!B97 -> -0.0014066213 | G3: =Sim_Regressions!B117 -> 0.0074872101 | H3: =Sim_Regressions!B137 -> -0.0006420251 | I3: =Sim_Regressions!B157 -> 0.010326954 | J3: 0 | L3: Equal weights | M3: =1/M1 -> 0.11111111
A4: Beta | B4: =Sim_Regressions!B18 -> 0.96828099 | C4: =Sim_Regressions!B38 -> 1.2116134 | D4: =Sim_Regressions!B58 -> 1.0267595 | E4: =Sim_Regressions!B78 -> 0.54607031 | F4: =Sim_Regressions!B98 -> 0.39888171 | G4: =Sim_Regressions!B118 -> 0.48280888 | H4: =Sim_Regressions!B138 -> 1.4496643 | I4: =Sim_Regressions!B158 -> 1.3017329 | J4: 1
A5: Idiosyncratic volatility / sigma_e | B5: =Sim_Regressions!B7 -> 0.072282484 | C5: =Sim_Regressions!B27 -> 0.091312553 | D5: =Sim_Regressions!B47 -> 0.044252582 | E5: =Sim_Regressions!B67 -> 0.039349004 | F5: =Sim_Regressions!B87 -> 0.048017357 | G5: =Sim_Regressions!B107 -> 0.047099282 | H5: =Sim_Regressions!B127 -> 0.061744302 | I5: =Sim_Regressions!B147 -> 0.10495369 | J5: 0
A6: sigma_m^2 | J6: =_xlfn.VAR.S(Data!K2:K97) -> 0.0021477665
A7: Risk premium / mu_m | J7: =AVERAGE('SIM-Data'!J5:J100) -> 0.0087210487
A8: Weights | B8: 0.011217138 | C8: -0.1818724 | D8: 0.34213061 | E8: 0.19281712 | F8: -0.10293758 | G8: 0.56946237 | H8: -0.028407854 | I8: 0.15818478 | J8: 0.039405812 | K8: =SUM(B8:J8) -> 1
A9: w*alpha | B9: =B8*B3 -> 3.8975433e-06 | C9: =C8*C3 -> 0.0016345123 | D9: =D8*D3 -> 0.0013585632 | E9: =E8*E3 -> 0.00034116255 | F9: =F8*F3 -> 0.0001447942 | G9: =G8*G3 -> 0.0042636844 | H9: =H8*H3 -> 1.8238555e-05 | I9: =I8*I3 -> 0.001633567 | J9: =J8*J3 -> 0 | K9: =SUM(B9:J9) -> 0.0093984198
A10: w*beta | B10: =B8*B4 -> 0.010861342 | C10: =C8*C4 -> -0.22035905 | D10: =D8*D4 -> 0.35128586 | E10: =E8*E4 -> 0.10529171 | F10: =F8*F4 -> -0.041059919 | G10: =G8*G4 -> 0.27494149 | H10: =H8*H4 -> -0.041181851 | I10: =I8*I4 -> 0.20591433 | J10: =J8*J4 -> 0.039405812 | K10: =SUM(B10:J10) -> 0.68509972
A11: w^2*sigma_e^2 | B11: =B8^2*B5^2 -> 6.574009e-07 | C11: =C8^2*C5^2 -> 0.0002758002 | D11: =D8^2*D5^2 -> 0.00022922453 | E11: =E8^2*E5^2 -> 5.7565023e-05 | F11: =F8^2*F5^2 -> 2.443118e-05 | G11: =G8^2*G5^2 -> 0.00071938045 | H11: =H8^2*H5^2 -> 3.0765971e-06 | I11: =I8^2*I5^2 -> 0.00027562894 | J11: =J8^2*J5^2 -> 0 | K11: =SUM(B11:J11) -> 0.0015857643
B13: Monthly | C13: Annualized
A14: Risk premium | B14: =K9+J7*K10 -> 0.015373208 | C14: =B14*12 -> 0.18447849
A15: Sigma_p^2 | B15: =K10^2*J6+K11 -> 0.0025938435 | C15: =B15*12 -> 0.031126122
A16: Sigma_p | B16: =SQRT(B15) -> 0.05092979 | C16: =B16*SQRT(12) -> 0.17642597
A17: Sharpe ratio | B17: =B14/B16 -> 0.301851 | C17: =B17*SQRT(12) -> 1.0456425
L21: n | M21: =COUNTA(B23:J23) -> 9
B22: Exxon Mobil Corp | C22: General Electric | D22: Home Depot Inc | E22: Johnson & Johnson | F22: Verizon Communications Inc | G22: Walmart Inc | H22: Bank of America Corp | I22: Netflix | J22: Market | K22: Total
A23: Alpha | B23: 0.00034746324 | C23: -0.0089871378 | D23: 0.0039708906 | E23: 0.0017693582 | F23: -0.0014066213 | G23: 0.0074872101 | H23: -0.0006420251 | I23: 0.010326954 | J23: 0 | L23: Equal weights | M23: =1/M21 -> 0.11111111
A24: Beta | B24: 0.96828099 | C24: 1.2116134 | D24: 1.0267595 | E24: 0.54607031 | F24: 0.39888171 | G24: 0.48280888 | H24: 1.4496643 | I24: 1.3017329 | J24: 1
A25: Idiosyncratic volatility / sigma_e | B25: 0.072282484 | C25: 0.091312553 | D25: 0.044252582 | E25: 0.039349004 | F25: 0.048017357 | G25: 0.047099282 | H25: 0.061744302 | I25: 0.10495369 | J25: 0
A26: sigma_m^2 | J26: 0.0021477665
A27: Risk premium / mu_m | J27: 0.0087210487
A28: Weights | B28: 0.011217138 | C28: -0.1818724 | D28: 0.34213061 | E28: 0.19281712 | F28: -0.10293758 | G28: 0.56946237 | H28: -0.028407854 | I28: 0.15818478 | J28: 0.039405812 | K28: 1
A29: w*alpha | B29: 3.8975433e-06 | C29: 0.0016345123 | D29: 0.0013585632 | E29: 0.00034116255 | F29: 0.0001447942 | G29: 0.0042636844 | H29: 1.8238555e-05 | I29: 0.001633567 | J29: 0 | K29: 0.0093984198
A30: w*beta | B30: 0.010861342 | C30: -0.22035905 | D30: 0.35128586 | E30: 0.10529171 | F30: -0.041059919 | G30: 0.27494149 | H30: -0.041181851 | I30: 0.20591433 | J30: 0.039405812 | K30: 0.68509972
A31: w^2*sigma_e^2 | B31: 6.574009e-07 | C31: 0.0002758002 | D31: 0.00022922453 | E31: 5.7565023e-05 | F31: 2.443118e-05 | G31: 0.00071938045 | H31: 3.0765971e-06 | I31: 0.00027562894 | J31: 0 | K31: 0.0015857643
B33: Monthly | C33: Annualized
A34: Risk premium | B34: 0.015373208 | C34: 0.18447849
A35: Sigma_p^2 | B35: 0.0025938435 | C35: 0.031126122
A36: Sigma_p | B36: 0.05092979 | C36: 0.17642597
A37: Sharpe ratio | B37: 0.301851 | C37: 1.0456425
